<mujoco model="ant">
  <!-- <include file="common/skybox.xml"/> -->
  <!-- <include file="common/visual.xml"/> -->
  <include file="common/materials.xml"/>

  <compiler angle="degree" inertiafromgeom="true"/>
  <option integrator="Euler" timestep="0.001" iterations="50" ls_iterations="50">
    <flag eulerdamp="disable"/>  
  </option>
  <default>
    <joint armature="0.5" damping="0.1" limited="true"/>
    <geom conaffinity="0" condim="3" density="5.0" friction="1 0.5 0.5" margin="0.01" material="self"/>
  </default>
  <asset>
    <!-- <texture type="skybox" builtin="gradient" rgb1="1 1 1" rgb2="1 1 1" width="800" height="800"/> -->
    <texture type="skybox" builtin="gradient" rgb1="1 1 1" rgb2="1 1 1" width="800" height="800"/>
    <texture type="2d" name="groundplane" builtin="checker" mark="edge" rgb1="1 1 1" rgb2="1 1 1"
      markrgb="0 0 0" width="300" height="300"/>
    <material name="groundplane" texture="groundplane" texuniform="true" texrepeat="5 5" reflectance="0"/>
  </asset>

  <visual>
    <headlight diffuse=".8 .8 .8" ambient=".2 .2 .2" specular="1 1 1"/>
    <rgba force="1 0 0 1"/>
    <global azimuth="140" elevation="-20" offwidth="2560" offheight="2560"/>
    <map force="0.01"/>
    <scale forcewidth="0.3" contactwidth="0.5" contactheight="0.2"/>
    <quality shadowsize="8192"/>
  </visual>

  <worldbody>
    <!-- <light cutoff="100" diffuse="1 1 1" dir="-0 0 -1.3" directional="true" exponent="1" pos="0 0 1.3" specular=".1 .1 .1"/> -->
    <!-- <light name="light" pos="0 0 2" mode="trackcom"/> -->
    <!-- <camera name="side_fixed" pos="4 -8 6" euler="70 0 0"/> -->
    <!-- <camera name="side_fixed" pos="4 -8 3" euler="85 0 0"/> -->
    <camera name="side_fixed" pos="2.0 -4.5 2.5" euler="70 0 0"/>
    <!-- <light name="lightx" pos="20 0 10" dir="-1 0 -1" mode="fixed" specular="1 1 1" diffuse=".8 .8 .8" ambient=".2 .2 .2"/> -->
    
    <light name="lightx" pos="22 0  20"    dir="-2 0 -9"    mode="fixed" specular="1 1 1" diffuse=".3 .3 .3" ambient=".2 .2 .2"/>
    <light name="lighty" pos="6  22 20"    dir="-4 -0.6 -9" mode="fixed" specular="1 1 1" diffuse=".3 .3 .3" ambient=".2 .2 .2"/>
    <light name="lightq" pos="-10 23 28"   dir="-1 -1 -7"   mode="fixed" specular="1 1 1" diffuse=".3 .3 .3" ambient=".2 .2 .2"/>
    <light name="lightw" pos="18 18 20"   dir="0 0 -9"      mode="fixed" specular="1 1 1" diffuse=".3 .3 .3" ambient=".1 .1 .1"/>
    <light name="lightz" pos="19 19 28"   dir="0 0 -9"      mode="fixed" specular="1 1 1" diffuse=".3 .3 .3" ambient=".2 .2 .2"/>
    <light name="lightt" pos="22 22 28"   dir="0 0 -9"      mode="fixed" specular="1 1 1" diffuse=".3 .3 .3" ambient=".2 .2 .2"/>
        
    <light name="light_overhead1" pos="0 0 40" dir="0 0 -1" mode="fixed" specular="1 1 1" diffuse="0.20 0.20 0.20" ambient="0.2 0.2 0.2"/>
    <!-- <light name="light_overhead2" pos="22 2 15" dir="-1 0 -1" mode="fixed" specular="0.55 0.55 0.55" diffuse="0.8 0.8 0.8" ambient="0.2 0.2 0.2"/> -->
    <geom name="ground" type="plane" conaffinity="1" pos="0 0 0" size="100 20 .5" material="groundplane"/>
    <body name="torso" pos="0 0 0.75">
      <camera name="track" mode="trackcom" pos="0 -5 3" xyaxes="1 0 0 0 0.6 1"/>
      <geom conaffinity="0" contype="0" name="torso_geom" pos="0 0 0" size="0.25" type="sphere"/>
      <joint armature="0" damping="0" limited="false" margin="0.01" name="root" pos="0 0 0" type="free"/>
      <body name="front_left_leg" pos="0 0 0">
        <geom conaffinity="0" contype="0" fromto="0.0 0.0 0.0 0.2 0.2 0.0" name="aux_1_geom" size="0.08" type="capsule"/>
        <body name="aux_1" pos="0.2 0.2 0">
          <joint axis="0 0 1" name="hip_1" pos="0.0 0.0 0.0" range="-30 30" type="hinge"/>
          <geom conaffinity="0" contype="0" fromto="0.0 0.0 0.0 0.2 0.2 0.0" name="left_leg_geom" size="0.08" type="capsule"/>
          <body pos="0.2 0.2 0">
            <joint axis="-1 1 0" name="ankle_1" pos="0.0 0.0 0.0" range="30 70" type="hinge"/>
            <geom fromto="0.0 0.0 0.0 0.4 0.4 0.0" name="left_ankle_geom" size="0.08" type="capsule"/>
          </body>
        </body>
      </body>
      <body name="front_right_leg" pos="0 0 0">
        <geom conaffinity="0" contype="0" fromto="0.0 0.0 0.0 -0.2 0.2 0.0" name="aux_2_geom" size="0.08" type="capsule"/>
        <body name="aux_2" pos="-0.2 0.2 0">
          <joint axis="0 0 1" name="hip_2" pos="0.0 0.0 0.0" range="-30 30" type="hinge"/>
          <geom conaffinity="0" contype="0" fromto="0.0 0.0 0.0 -0.2 0.2 0.0" name="right_leg_geom" size="0.08" type="capsule"/>
          <body pos="-0.2 0.2 0">
            <joint axis="1 1 0" name="ankle_2" pos="0.0 0.0 0.0" range="-70 -30" type="hinge"/>
            <geom fromto="0.0 0.0 0.0 -0.4 0.4 0.0" name="right_ankle_geom" size="0.08" type="capsule"/>
          </body>
        </body>
      </body>
      <body name="back_leg" pos="0 0 0">
        <geom conaffinity="0" contype="0" fromto="0.0 0.0 0.0 -0.2 -0.2 0.0" name="aux_3_geom" size="0.08" type="capsule"/>
        <body name="aux_3" pos="-0.2 -0.2 0">
          <joint axis="0 0 1" name="hip_3" pos="0.0 0.0 0.0" range="-30 30" type="hinge"/>
          <geom conaffinity="0" contype="0" fromto="0.0 0.0 0.0 -0.2 -0.2 0.0" name="back_leg_geom" size="0.08" type="capsule"/>
          <body pos="-0.2 -0.2 0">
            <joint axis="-1 1 0" name="ankle_3" pos="0.0 0.0 0.0" range="-70 -30" type="hinge"/>
            <geom fromto="0.0 0.0 0.0 -0.4 -0.4 0.0" name="third_ankle_geom" size="0.08" type="capsule"/>
          </body>
        </body>
      </body>
      <body name="right_back_leg" pos="0 0 0">
        <geom conaffinity="0" contype="0" fromto="0.0 0.0 0.0 0.2 -0.2 0.0" name="aux_4_geom" size="0.08" type="capsule"/>
        <body name="aux_4" pos="0.2 -0.2 0">
          <joint axis="0 0 1" name="hip_4" pos="0.0 0.0 0.0" range="-30 30" type="hinge"/>
          <geom conaffinity="0" contype="0" fromto="0.0 0.0 0.0 0.2 -0.2 0.0" name="rightback_leg_geom" size="0.08" type="capsule"/>
          <body pos="0.2 -0.2 0">
            <joint axis="1 1 0" name="ankle_4" pos="0.0 0.0 0.0" range="30 70" type="hinge"/>
            <geom fromto="0.0 0.0 0.0 0.4 -0.4 0.0" name="fourth_ankle_geom" size="0.08" type="capsule"/>
          </body>
        </body>
      </body>
    </body>
  </worldbody>
  <actuator>
    <motor ctrllimited="true" ctrlrange="-1.0 1.0" joint="hip_4"   gear="100"/>
    <motor ctrllimited="true" ctrlrange="-1.0 1.0" joint="ankle_4" gear="100"/>
    <motor ctrllimited="true" ctrlrange="-1.0 1.0" joint="hip_1"   gear="100"/>
    <motor ctrllimited="true" ctrlrange="-1.0 1.0" joint="ankle_1" gear="100"/>
    <motor ctrllimited="true" ctrlrange="-1.0 1.0" joint="hip_2"   gear="100"/>
    <motor ctrllimited="true" ctrlrange="-1.0 1.0" joint="ankle_2" gear="100"/>
    <motor ctrllimited="true" ctrlrange="-1.0 1.0" joint="hip_3"   gear="100"/>
    <motor ctrllimited="true" ctrlrange="-1.0 1.0" joint="ankle_3" gear="100"/>
  </actuator>
  <sensor>
    <framezaxis name="torso_z" objtype="body" objname="torso"/>
  </sensor>
</mujoco>