<mujoco model="planar hopper">
  <!-- <include file="common/skybox.xml"/> -->
  <!-- <include file="common/visual.xml"/> -->
  <include file="common/materials.xml"/>

  <!-- <statistic extent="2" center="0 0 .5"/> -->

  <default>
    <default class="hopper">
      <joint type="hinge" axis="0 1 0" limited="true" damping=".05" armature=".2"/>
      <geom type="capsule" material="self" conaffinity="0" contype="0"/>
      <site type="sphere" size="0.05" group="3"/>
    </default>
    <default class="free">
      <joint limited="false" damping="0" armature="0" stiffness="0"/>
    </default>
    <motor ctrllimited="false"/>
  </default>

  <asset>
    <!-- <texture type="skybox" builtin="gradient" rgb1="1 1 1" rgb2="1 1 1" width="800" height="800"/> -->
    <texture type="skybox" builtin="gradient" rgb1="1 1 1" rgb2="1 1 1" width="800" height="800"/>
    <texture type="2d" name="groundplane" builtin="checker" mark="edge" rgb1="1 1 1" rgb2="1 1 1"
      markrgb="0 0 0" width="300" height="300"/>
    <material name="groundplane" texture="groundplane" texuniform="true" texrepeat="5 5" reflectance="0"/>
  </asset>

  <visual>
    <headlight diffuse=".8 .8 .8" ambient=".2 .2 .2" specular="1 1 1"/>
    <rgba force="1 0 0 1"/>
    <global azimuth="140" elevation="-20" offwidth="2560" offheight="2560"/>
    <map force="0.01"/>
    <scale forcewidth="0.3" contactwidth="0.5" contactheight="0.2"/>
    <quality shadowsize="8192"/>
    <!-- <quality shadowsize="2048"/> -->
  </visual>

  <option timestep="0.005" iterations="4" ls_iterations="10">
    <flag eulerdamp="disable"/>
  </option>

  <custom>
    <numeric data="6" name="max_contact_points"/>
    <numeric data="2" name="max_geom_pairs"/>
  </custom>

  <worldbody>
    <camera name="side_fixed" pos="4.0 -7.5 1.0" euler="80 0 0"/>
    <camera name="track" pos="0 -2.8 -0.5" euler="90 0 0" mode="trackcom"/>
    <camera name="back" pos="-2 -.2 1.2" xyaxes="0.2 -1 0 .5 0 2" mode="trackcom"/>
    <geom name="floor" type="plane" conaffinity="1" pos="48 0 0" size="50 1 .2" material="groundplane"/>
    <light name="light" pos="20 0 10" dir="-1 0 -1" mode="fixed" specular="1 1 1" diffuse=".8 .8 .8" ambient=".2 .2 .2"/>
    <body name="torso" pos="0 0 0" childclass="hopper">
      <joint name="rootx" type="slide" axis="1 0 0" class="free"/>
      <joint name="rootz" type="slide" axis="0 0 1" class="free"/>
      <joint name="rooty" type="hinge" axis="0 1 0" class="free"/>
      <geom name="torso" fromto="0 0 -.05 0 0 .2" size="0.0653"/>
      <geom name="nose" fromto=".08 0 .13 .15 0 .14" size="0.03"/>
      <body name="pelvis" pos="0 0 -.05">
        <joint name="waist" range="-30 30"/>
        <geom name="pelvis" fromto="0 0 0 0 0 -.15" size="0.065"/>
        <body name="thigh" pos="0 0 -.2">
          <joint name="hip" range="-170 10"/>
          <geom name="thigh" fromto="0 0 0 0 0 -.33" size="0.04"/>
          <body name="calf" pos="0 0 -.33">
            <joint name="knee" range="5 150"/>
            <geom name="calf" fromto="0 0 0 0 0 -.32" size="0.03"/>
            <body name="foot" pos="0 0 -.32">
              <joint name="ankle" range="-45 45"/>
              <geom name="foot" fromto="-.08 0 0 .17 0 0" size="0.04"/>
              <site name="touch_toe" pos=".17 0 0"/>
              <site name="touch_heel" pos="-.08 0 0"/>
            </body>
          </body>
        </body>
      </body>
    </body>
  </worldbody>

  <contact>
    <pair name="foot_floor" geom1="foot" geom2="floor" condim="3" friction="0.7 0.7"/>
  </contact>

  <sensor>
    <subtreelinvel name="torso_subtreelinvel" body="torso"/>
    <touch name="touch_toe" site="touch_toe"/>
    <touch name="touch_heel" site="touch_heel"/>
  </sensor>

  <actuator>
    <motor name="waist" joint="waist" gear="30"/>
    <motor name="hip" joint="hip" gear="40"/>
    <motor name="knee" joint="knee" gear="30"/>
    <motor name="ankle" joint="ankle" gear="10"/>
  </actuator>
</mujoco>